(dp1
S'output'
p2
S'<type \'exceptions.RuntimeError\'> Failure to connect, tried 5 times:\nTraceback (most recent call last):\n  File "/home/desarrollo/myapp/sismun/web2py/gluon/dal.py", line 7845, in __init__\n    self._adapter = ADAPTERS[self._dbname](**kwargs)\n  File "/home/desarrollo/myapp/sismun/web2py/gluon/dal.py", line 688, in __call__\n    obj = super(AdapterMeta, cls).__call__(*args, **kwargs)\n  File "/home/desarrollo/myapp/sismun/web2py/gluon/dal.py", line 2870, in __init__\n    if do_connect: self.reconnect()\n  File "/home/desarrollo/myapp/sismun/web2py/gluon/dal.py", line 648, in reconnect\n    self.connection = f()\n  File "/home/desarrollo/myapp/sismun/web2py/gluon/dal.py", line 2868, in connector\n    return self.driver.connect(msg,**driver_args)\n  File "/home/desarrollo/myapp/sismun/web2py/gluon/contrib/pg8000/dbapi.py", line 752, in connect\n    password=password, socket_timeout=socket_timeout, ssl=ssl)\n  File "/home/desarrollo/myapp/sismun/web2py/gluon/contrib/pg8000/dbapi.py", line 483, in __init__\n    self.conn = interface.Connection(**kwargs)\n  File "/home/desarrollo/myapp/sismun/web2py/gluon/contrib/pg8000/interface.py", line 537, in __init__\n    self.c.authenticate(user, password=password, database=database)\n  File "/home/desarrollo/myapp/sismun/web2py/gluon/contrib/pg8000/protocol.py", line 1051, in authenticate\n    reader.handle_messages()\n  File "/home/desarrollo/myapp/sismun/web2py/gluon/contrib/pg8000/protocol.py", line 911, in handle_messages\n    retval = handler(msg, *args, **kwargs)\n  File "/home/desarrollo/myapp/sismun/web2py/gluon/contrib/pg8000/protocol.py", line 1058, in _func\n    if not msg.ok(self, user, **kwargs):\n  File "/home/desarrollo/myapp/sismun/web2py/gluon/contrib/pg8000/protocol.py", line 467, in ok\n    return reader.handle_messages()\n  File "/home/desarrollo/myapp/sismun/web2py/gluon/contrib/pg8000/protocol.py", line 911, in handle_messages\n    retval = handler(msg, *args, **kwargs)\n  File "/home/desarrollo/myapp/sismun/web2py/gluon/contrib/pg8000/protocol.py", line 473, in _ok_error\n    raise msg.createException()\nProgrammingError: (\'FATAL\', \'28P01\', \'password authentication failed for user "web2py"\')\n'
p3
sS'layer'
p4
S'/home/desarrollo/myapp/sismun/web2py/applications/mapsnews/models/db.py'
p5
sS'code'
p6
S'# -*- coding: utf-8 -*-\n\n# -*- coding: utf-8 -*-\ndb = DAL(\'postgres://web2py:web2py@localhost:5432/testw2p\', lazy_tables=False,)\ndb.define_table(\'geostuff\',\n    Field(\'name\', \'string\'),\n    Field(\'geometry\', \'geometry()\'),\n    )\nn_rows = db(db.geostuff).count()\nif not n_rows:\n    db.geostuff.insert(name="My first geo point (London!)", geometry="POINT(-0.091109 51.512622)")\n    db.geostuff.insert(name="My first linestring", geometry="LINESTRING (8.791595 45.660281, 11.343062 44.494932, 10.394590 43.722998)")\n'
p7
sS'snapshot'
p8
(dp9
sS'traceback'
p10
S'Traceback (most recent call last):\n  File "/home/desarrollo/myapp/sismun/web2py/gluon/restricted.py", line 220, in restricted\n    exec ccode in environment\n  File "/home/desarrollo/myapp/sismun/web2py/applications/mapsnews/models/db.py", line 4, in <module>\n    db = DAL(\'postgres://web2py:web2py@localhost:5432/testw2p\', lazy_tables=False,)\n  File "/home/desarrollo/myapp/sismun/web2py/gluon/dal.py", line 7867, in __init__\n    raise RuntimeError("Failure to connect, tried %d times:\\n%s" % (attempts, tb))\nRuntimeError: Failure to connect, tried 5 times:\nTraceback (most recent call last):\n  File "/home/desarrollo/myapp/sismun/web2py/gluon/dal.py", line 7845, in __init__\n    self._adapter = ADAPTERS[self._dbname](**kwargs)\n  File "/home/desarrollo/myapp/sismun/web2py/gluon/dal.py", line 688, in __call__\n    obj = super(AdapterMeta, cls).__call__(*args, **kwargs)\n  File "/home/desarrollo/myapp/sismun/web2py/gluon/dal.py", line 2870, in __init__\n    if do_connect: self.reconnect()\n  File "/home/desarrollo/myapp/sismun/web2py/gluon/dal.py", line 648, in reconnect\n    self.connection = f()\n  File "/home/desarrollo/myapp/sismun/web2py/gluon/dal.py", line 2868, in connector\n    return self.driver.connect(msg,**driver_args)\n  File "/home/desarrollo/myapp/sismun/web2py/gluon/contrib/pg8000/dbapi.py", line 752, in connect\n    password=password, socket_timeout=socket_timeout, ssl=ssl)\n  File "/home/desarrollo/myapp/sismun/web2py/gluon/contrib/pg8000/dbapi.py", line 483, in __init__\n    self.conn = interface.Connection(**kwargs)\n  File "/home/desarrollo/myapp/sismun/web2py/gluon/contrib/pg8000/interface.py", line 537, in __init__\n    self.c.authenticate(user, password=password, database=database)\n  File "/home/desarrollo/myapp/sismun/web2py/gluon/contrib/pg8000/protocol.py", line 1051, in authenticate\n    reader.handle_messages()\n  File "/home/desarrollo/myapp/sismun/web2py/gluon/contrib/pg8000/protocol.py", line 911, in handle_messages\n    retval = handler(msg, *args, **kwargs)\n  File "/home/desarrollo/myapp/sismun/web2py/gluon/contrib/pg8000/protocol.py", line 1058, in _func\n    if not msg.ok(self, user, **kwargs):\n  File "/home/desarrollo/myapp/sismun/web2py/gluon/contrib/pg8000/protocol.py", line 467, in ok\n    return reader.handle_messages()\n  File "/home/desarrollo/myapp/sismun/web2py/gluon/contrib/pg8000/protocol.py", line 911, in handle_messages\n    retval = handler(msg, *args, **kwargs)\n  File "/home/desarrollo/myapp/sismun/web2py/gluon/contrib/pg8000/protocol.py", line 473, in _ok_error\n    raise msg.createException()\nProgrammingError: (\'FATAL\', \'28P01\', \'password authentication failed for user "web2py"\')\n\n'
p11
s.